Workbook
Name __AD1: #REF!
Name __D3: #REF!
Name __DAT1: #REF!
Name __DAT10: #REF!
Name __DAT11: #REF!
Name __DAT12: '[4]C. PENSION'!#REF!
Name __DAT2: #REF!
Name __DAT3: #REF!
Name __DAT4: #REF!
Name __DAT5: #REF!
Name __DAT6: #REF!
Name __DAT7: #REF!
Name __DAT8: #REF!
Name __DAT9: #REF!
Name __T1: #REF!
Name __T2: #REF!
Name __T5: #REF!
Name _1P68: '[6]%'!$B$2:$Z$17
Name _2P68: #REF!
Name _55: [8]Macro1!$B$29:$C$29
Name _55_F: [9]Macro1!$B$159:$C$159
Name _55_H: [9]Macro1!$B$94:$C$94
Name _56: [10]Macro1!#REF!
Name _56_59: [10]Macro1!#REF!
Name _56_a_59: [8]Macro1!$B$31:$C$31
Name _56_a_59_F: [9]Macro1!$B$161:$C$161
Name _56_a_59_H: [9]Macro1!$B$96:$C$96
Name _57: [10]Macro1!#REF!
Name _58: [10]Macro1!#REF!
Name _59: [10]Macro1!#REF!
Name _60: [8]Macro1!$B$34:$C$34
Name _60_F: [9]Macro1!$B$164:$C$164
Name _60_H: [9]Macro1!$B$99:$C$99
Name _61: [10]Macro1!#REF!
Name _61_64: [10]Macro1!#REF!
Name _61_a_64: [8]Macro1!$B$36:$C$36
Name _61_a_64_F: [9]Macro1!$B$166:$C$166
Name _61_a_64_H: [9]Macro1!$B$101:$C$101
Name _62: [10]Macro1!#REF!
Name _63: [10]Macro1!#REF!
Name _64: [10]Macro1!#REF!
Name _65: [8]Macro1!$B$39:$C$39
Name _65_et_plus: [10]Macro1!#REF!
Name _65_F: [9]Macro1!$B$169:$C$169
Name _65_H: [9]Macro1!$B$104:$C$104
Name _66_et_plus: [8]Macro1!$B$41:$C$41
Name _66_et_plus_F: [9]Macro1!$B$171:$C$171
Name _66_et_plus_H: [9]Macro1!$B$106:$C$106
Name _AD1: #REF!
Name _D3: #REF!
Name _DAT1: #REF!
Name _DAT10: #REF!
Name _DAT11: #REF!
Name _DAT12: '[4]C. PENSION'!#REF!
Name _DAT13: [11]mensual!#REF!
Name _DAT14: [11]mensual!#REF!
Name _DAT2: #REF!
Name _DAT3: #REF!
Name _DAT4: #REF!
Name _DAT5: #REF!

Sheet SOMMAIRE
A1: Rapport droits familiaux et conjugaux
A3: Fichiers sources des tableaux et figures
A5: Annexes données détaillées
A7: Annexe A. Les bénéficiaires des droits familiaux par régime et en projection
A9: ='Fig A.1'!A1 -> Figure A.1 - Part des retraitées de droit propre bénéficiaires de la MDA par génération et nombre moyen de trimestres validés au titre de la MDA selon le régime considéré - Femmes
A10: ='Fig A.2'!A1 -> Figure A.2 - Durées d’assurance avec et sans MDA selon le nombre d’enfants pour les femmes retraitées, par génération
A11: ='Fig A.3'!A1 -> Figure A.3 - Durées d’assurance avec et sans MDA selon le nombre d’enfants pour les femmes retraitées de la CNAV, par génération
A12: ='Fig A.4'!A1 -> Figure A.4 - Durées d’assurance avec et sans MDA selon le nombre d’enfants pour les femmes retraitées du SRE, par génération
A13: ='Fig A.5'!A1 -> Figure A.5 - Part des retraitées de droit propre bénéficiaires de l’AVPF par génération et nombre moyen de trimestres validés à ce titre – Cnav
A14: ='Fig A.6'!A1 -> Figure A.6 - Part des retraités de droit propre bénéficiaires de la majoration de pension pour trois enfants et plus, par génération et régime
A15: ='Fig A.7'!A1 -> Figure A.7 - Part des bénéficiaires des départs anticipés pour 3 enfants et âge moyen de départ, par génération
A16: ='Fig A.8'!A1 -> Figure A.8 - Part des bénéficiaires des départs anticipés pour 3 enfants et âge moyen de départ, par génération et par régime
A17: ='Fig A.9'!A1 -> Figure A.9 - Âge moyen de départ à la retraite des femmes bénéficiaires du dispositif et des femmes de 3 enfants et plus, par génération et par régime
A20: Annexe B. Résultats détaillés des simulations d'harmonisation des droits familiaux et conjugaux
A22: ='Tab B.1'!A1 -> Tableau B.1 - Attribution de 8 trimestres de MDA quel que soit le régime d’affiliation - génération 2000
A23: ='Tab B.2'!A1 -> Tableau B.2 - Attribution de 4 trimestres de MDA quel que soit le régime d’affiliation - génération 2000
A24: ='Tab B.3'!A1 -> Tableau B.3 - Attribution de 2 trimestres de MDA quel que soit le régime d’affiliation - génération 2000
A25: ='Tab B.4'!A1 -> Tableau B.4 - Harmonisation de la majoration de pension à 10 % quel que soit le régime et uniformisation au-delà du troisième enfant - génération 2000
A26: ='Tab B.5'!A1 -> Tableau B.5 - Écart de masses de prestations de droit direct par régimes après mesures (en %)
A27: ='Fig B.1'!A1 -> Figure B.1 - Impact de la suppression de la condition de ressources sur la pension moyenne sur cycle de vie des assurés de la génération 2000 (en %)
A28: ='Fig B.2'!A1 -> Figure B.2 - Impact de la génératlisation de la condition de ressources sur la pension moyenne sur cycle de vie des assurés de la génération 2000 (en %)
A29: ='Fig B.3'!A1 -> Figure B.3 - Ecart après mesures d'harmonisation (croisement) des masses de prestations de droit dérivé (en %)
A32: Annexe C. Résultats détaillés des simulations d'évolution des droits familiaux et conjugaux
A34: ='Tab C.1'!A1 -> Tableau C.1 - Principaux résultats de la simulation d’évolution des droits familiaux : MDA, majorations proportionnelles avec taux progressifs selon le nombre d’enfants, bornage de l’AVPF - génération 2000 (avec plafonnement)
A35: ='Tab C.2'!A1 -> Tableau C.2 - Principaux résultats de la simulation d’évolution des droits familiaux : MDA, majorations proportionnelles avec taux progressifs selon le nombre d’enfants, bornage de l’AVPF - génération 1966 (avec plafonnement)
A36: ='Tab C.3'!A1 -> Tableau C.3 - Principaux résultats de la simulation d’évolution des droits familiaux : MDA, majorations proportionnelles avec taux progressifs selon le nombre d’enfants, bornage de l’AVPF - génération 2000 (hors plafonnement)
A37: ='Tab C.4'!A1 -> Tableau C.4 - Principaux résultats de la simulation d’évolution des droits familiaux : MDA, majorations proportionnelles avec taux progressifs selon le nombre d’enfants, bornage de l’AVPF - génération 1966 (hors plafonnement)
A38: ='Tab C.5'!A1 -> Tableau C.5 - Écart de masses de prestations de droit direct par régimes après mesures (en %)
A39: ='Fig C.1'!A1 -> Figure C.1 - Écart après mesure de maintien de niveau de vie des masses de prestations de droit dérivé selon le régime (en %)
A40: ='Fig C.2'!A1 -> Figure C.2 - Écarts de masses de prestations de réversion et de bénéficiaires de réversion après mesure de la double proratisation de pension de réversion (en %)
A41: ='Fig C.3'!A1 -> Figure C.3 - Écart de masses de prestations de droit dérivé selon le régime après mesure de double proratisation de la pension de réversion (en %)
A42: ='Fig C.4'!A1 -> Figure C.4 - Impact de la double proratisation de la réversion sur la pension sur cycle de vie des assurés de la génération 2000
A45: Annexe 4. Résultats détaillés de la variante de bascule des droits conjugaux vers les droits familiaux
A47: ='Tab D.1'!A1 -> Tableau D.1 - Principaux résultats de la simulation de bascule des droits conjugaux vers les droits familiaux - droits directs génération 2000 (avec plafonnement)
A48: ='Tab D.2'!A1 -> Tableau D.2 - Principaux résultats de la simulation de bascule des droits conjugaux vers les droits familiaux - droits directs génération 1966 (avec plafonnement)
A49: ='Tab D.3'!A1 -> Tableau D.3 - Principaux résultats de la simulation de bascule des droits conjugaux vers les droits familiaux - droits directs génération 2000 (hors plafonnement)
A50: ='Tab D.4'!A1 -> Tableau D.4 - Principaux résultats de la simulation de bascule des droits conjugaux vers les droits familiaux - réversion génération 2000
A51: ='Tab D.5'!A1 -> Tableau D.5 - Principaux résultats de la simulation de bascule des droits conjugaux vers les droits familiaux - réversion génération 1966
A52: ='Tab D.6'!A1 -> Tableau D.6 - Principaux résultats de la simulation de bascule des droits conjugaux vers les droits familiaux - droits directs et réversion génération 2000 (avec plafonnement)
A53: ='Tab D.7'!A1 -> Tableau D.7 - Principaux résultats de la simulation de bascule des droits conjugaux vers les droits familiaux - droits directs et réversion génération 1966 (avec plafonnement)
...

Sheet Fig A.1
A1: Figure A.1 - Part des retraitées de droit propre bénéficiaires de la MDA par génération et nombre moyen de trimestres validés au titre de la MDA selon le régime considéré - Femmes
A2: Retour au sommaire
D4: 1930 | E4: 1931 | F4: 1932 | G4: 1933 | H4: 1934 | I4: 1935 | J4: 1936 | K4: 1937 | L4: 1938 | M4: 1939 | N4: 1940 | O4: 1941 | P4: 1942 | Q4: 1943 | R4: 1944 | S4: 1945 | T4: 1946 | U4: 1947 | V4: 1948 | W4: 1949 | X4: 1950 | Y4: 1951 | Z4: 1952 | AA4: 1953 | AB4: 1954 | AC4: 1955 | AD4: 1956 | AE4: 1957 | AF4: 1958 | AG4: 1959 | AH4: 1960 | AI4: 1961 | AJ4: 1962 | AK4: 1963 | AL4: 1964 | AM4: 1965 | AN4: 1966 | AO4: 1967 | AP4: 1968 | AQ4: 1969 | AR4: 1970 | AS4: 1971 | AT4: 1972 | AU4: 1973 | AV4: 1974 | AW4: 1975 | AX4: 1976 | AY4: 1977 | AZ4: 1978 | BA4: 1979 | BB4: 1980 | BC4: 1981 | BD4: 1982 | BE4: 1983 | BF4: 1984 | BG4: 1985 | BH4: 1986 | BI4: 1987 | BJ4: 1988 | BK4: 1989 | BL4: 1990 | BM4: 1991 | BN4: 1992 | BO4: 1993 | BP4: 1994 | BQ4: 1995 | BR4: 1996 | BS4: 1997 | BT4: 1998 | BU4: 1999 | BV4: 2000
B5: Part des bénéficiaires | C5: Cnav | G5: =[32]Effectifs!E10 -> 0.7853685 | H5: =[32]Effectifs!F10 -> 0.79913733 | I5: =[32]Effectifs!G10 -> 0.80384635 | J5: =[32]Effectifs!H10 -> 0.81107167 | K5: =[32]Effectifs!I10 -> 0.81574587 | L5: =[32]Effectifs!J10 -> 0.82130399 | M5: =[32]Effectifs!K10 -> 0.82682339 | N5: =[32]Effectifs!L10 -> 0.83257256 | ... BV5: =[32]Effectifs!BT10 -> 0.85640699
C6: SRE - civils | S6: =[33]Effectifs!Q10 -> 0.76390606 | T6: =[33]Effectifs!R10 -> 0.76151565 | U6: =[33]Effectifs!S10 -> 0.75659949 | V6: =[33]Effectifs!T10 -> 0.75061673 | W6: =[33]Effectifs!U10 -> 0.75375912 | X6: =[33]Effectifs!V10 -> 0.75974023 | Y6: =[33]Effectifs!W10 -> 0.7679029 | Z6: =[33]Effectifs!X10 -> 0.78314777 | ... BV6: =[33]Effectifs!BT10 -> 0.74060427
C7: CNRACL | D7: =[34]Effectifs!B12 -> 0.7135373 | E7: =[34]Effectifs!C12 -> 0.75471331 | F7: =[34]Effectifs!D12 -> 0.77788065 | G7: =[34]Effectifs!E12 -> 0.79288953 | H7: =[34]Effectifs!F12 -> 0.80302016 | I7: =[34]Effectifs!G12 -> 0.81881508 | J7: =[34]Effectifs!H12 -> 0.82047989 | K7: =[34]Effectifs!I12 -> 0.83360966 | ... AH7: =[34]Effectifs!AF12 -> 0.87599474
B8: Nombre moyen de trimestres validés | C8: Cnav | G8: =[32]Durées!F55 -> 21.340301 | H8: =[32]Durées!G55 -> 21.538147 | I8: =[32]Durées!H55 -> 21.520585 | J8: =[32]Durées!I55 -> 21.44975 | K8: =[32]Durées!J55 -> 21.310889 | L8: =[32]Durées!K55 -> 21.154698 | M8: =[32]Durées!L55 -> 20.912521 | N8: =[32]Durées!M55 -> 20.575602 | ... BV8: =[32]Durées!BU55 -> 15.296465
C9: SRE - civils | S9: =[33]Durées!R55 -> 8.0841424 | T9: =[33]Durées!S55 -> 7.982695 | U9: =[33]Durées!T55 -> 7.9296689 | V9: =[33]Durées!U55 -> 7.8650652 | W9: =[33]Durées!V55 -> 7.8359321 | X9: =[33]Durées!W55 -> 7.8453515 | Y9: =[33]Durées!X55 -> 7.8495559 | Z9: =[33]Durées!Y55 -> 7.9179199 | ... BV9: =[33]Durées!BU55 -> 4.2069652
C10: CNRACL | D10: =[34]Durées!C58 -> 10.596182 | E10: =[34]Durées!D58 -> 10.639712 | F10: =[34]Durées!E58 -> 10.612854 | G10: =[34]Durées!F58 -> 10.560337 | H10: =[34]Durées!G58 -> 10.268087 | I10: =[34]Durées!H58 -> 10.368707 | J10: =[34]Durées!I58 -> 10.415026 | K10: =[34]Durées!J58 -> 10.258393 | ... AH10: =[34]Durées!AG58 -> 9.5026858
B12: Note : ensemble des trimestres validés au titre de la MDA, que ces derniers soient utiles ou non au moment du départ à la retraite. Les données CNRACL sont en cours de consolidation.
B13: Champ : ensemble des femmes retraitées de droit direct.
B14: Source : Cnav modèle Prisme, SRE modèle Pablo, CNRACL modèle Canopée.
C17: Part des bénéficiaires | I17: Nombre moyen de trimestres validés

Sheet Fig A.2
A1: Figure A.2 - Durées d’assurance avec et sans MDA selon le nombre d’enfants pour les femmes retraitées, par génération
A2: Retour au sommaire
C4: 1930 | D4: 1931 | E4: 1932 | F4: 1933 | G4: 1934 | H4: 1935 | I4: 1936 | J4: 1937 | K4: 1938 | L4: 1939 | M4: 1940 | N4: 1941 | O4: 1942 | P4: 1943 | Q4: 1944 | R4: 1945 | S4: 1946 | T4: 1947 | U4: 1948 | V4: 1949 | W4: 1950 | X4: 1951 | Y4: 1952 | Z4: 1953
B5: Non bénéficiaires de la MDA | C5: =[35]Durées!C296 -> 128.14882 | D5: =[35]Durées!D296 -> 132.74238 | E5: =[35]Durées!E296 -> 134.14662 | F5: =[35]Durées!F296 -> 133.30425 | G5: =[35]Durées!G296 -> 134.05289 | H5: =[35]Durées!H296 -> 133.67792 | I5: =[35]Durées!I296 -> 134.15704 | J5: =[35]Durées!J296 -> 135.05068 | ... Z5: =[35]Durées!Z296 -> 148.06548
B6: 1 ou 2 enfants y compris MDA | C6: =[35]Durées!C297 -> 121.43086 | D6: =[35]Durées!D297 -> 122.27322 | E6: =[35]Durées!E297 -> 122.12358 | F6: =[35]Durées!F297 -> 121.75791 | G6: =[35]Durées!G297 -> 122.4706 | H6: =[35]Durées!H297 -> 123.49156 | I6: =[35]Durées!I297 -> 125.00781 | J6: =[35]Durées!J297 -> 126.1656 | ... Z6: =[35]Durées!Z297 -> 157.41824
B7: 3 enfants et plus y compris MDA | C7: =[35]Durées!C298 -> 112.74982 | D7: =[35]Durées!D298 -> 113.62812 | E7: =[35]Durées!E298 -> 115.45929 | F7: =[35]Durées!F298 -> 116.95203 | G7: =[35]Durées!G298 -> 118.21736 | H7: =[35]Durées!H298 -> 118.80682 | I7: =[35]Durées!I298 -> 119.45882 | J7: =[35]Durées!J298 -> 121.50375 | ... Z7: =[35]Durées!Z298 -> 158.21176
B8: 1 ou 2 enfants hors MDA | C8: =[35]Durées!C300 -> 110.11352 | D8: =[35]Durées!D300 -> 110.90308 | E8: =[35]Durées!E300 -> 110.69509 | F8: =[35]Durées!F300 -> 110.35257 | G8: =[35]Durées!G300 -> 110.96644 | H8: =[35]Durées!H300 -> 111.87478 | I8: =[35]Durées!I300 -> 113.235 | J8: =[35]Durées!J300 -> 114.35132 | ... Z8: =[35]Durées!Z300 -> 144.9038
B9: 3 enfants et plus hors MDA | C9: =[35]Durées!C301 -> 83.278295 | D9: =[35]Durées!D301 -> 84.869327 | E9: =[35]Durées!E301 -> 86.797885 | F9: =[35]Durées!F301 -> 88.08394 | G9: =[35]Durées!G301 -> 89.3101 | H9: =[35]Durées!H301 -> 90.071077 | I9: =[35]Durées!I301 -> 90.929043 | J9: =[35]Durées!J301 -> 93.20943 | ... Z9: =[35]Durées!Z301 -> 131.38146
B11: Note : ensemble des trimestres validés au titre de la MDA, que ces derniers soient utiles ou non au moment du départ à la retraite.
B12: Champ : ensemble des retraités de droit direct résidant en France et à l’étranger, pondérés pour être représentatifs des assurés ayant perçu une pension.
B13: Source : DREES, EIR 2020.

Sheet Fig A.3
A1: Figure A.3 - Durées d’assurance avec et sans MDA selon le nombre d’enfants pour les femmes retraitées de la CNAV, par génération
A2: Retour au sommaire
C4: 1933 | D4: 1934 | E4: 1935 | F4: 1936 | G4: 1937 | H4: 1938 | I4: 1939 | J4: 1940 | K4: 1941 | L4: 1942 | M4: 1943 | N4: 1944 | O4: 1945 | P4: 1946 | Q4: 1947 | R4: 1948 | S4: 1949 | T4: 1950 | U4: 1951 | V4: 1952 | W4: 1953 | X4: 1954 | Y4: 1955 | Z4: 1956 | AA4: 1957 | AB4: 1958 | AC4: 1959 | AD4: 1960 | AE4: 1961 | AF4: 1962 | AG4: 1963 | AH4: 1964 | AI4: 1965 | AJ4: 1966 | AK4: 1967 | AL4: 1968 | AM4: 1969 | AN4: 1970 | AO4: 1971 | AP4: 1972 | AQ4: 1973 | AR4: 1974 | AS4: 1975 | AT4: 1976 | AU4: 1977 | AV4: 1978 | AW4: 1979 | AX4: 1980 | AY4: 1981 | AZ4: 1982 | BA4: 1983 | BB4: 1984 | BC4: 1985 | BD4: 1986 | BE4: 1987 | BF4: 1988 | BG4: 1989 | BH4: 1990 | BI4: 1991 | BJ4: 1992 | BK4: 1993 | BL4: 1994 | BM4: 1995 | BN4: 1996 | BO4: 1997 | BP4: 1998 | BQ4: 1999 | BR4: 2000
B5: Non bénéficiaires de la MDA | C5: =[32]Durées!F199 -> 128.69 | D5: =[32]Durées!G199 -> 134.29333 | E5: =[32]Durées!H199 -> 136.176 | F5: =[32]Durées!I199 -> 138.442 | G5: =[32]Durées!J199 -> 139.778 | H5: =[32]Durées!K199 -> 141.196 | I5: =[32]Durées!L199 -> 142.342 | J5: =[32]Durées!M199 -> 143.82 | ... BR5: =[32]Durées!BU199 -> 155.33
B6: 1 ou 2 enfants y compris MDA | C6: =[32]Durées!F200 -> 116.39 | D6: =[32]Durées!G200 -> 115.53667 | E6: =[32]Durées!H200 -> 116.994 | F6: =[32]Durées!I200 -> 118.162 | G6: =[32]Durées!J200 -> 120.184 | H6: =[32]Durées!K200 -> 122.276 | I6: =[32]Durées!L200 -> 124.622 | J6: =[32]Durées!M200 -> 127.038 | ... BR6: =[32]Durées!BU200 -> 159.4
B7: 3 enfants et plus y compris MDA | C7: =[32]Durées!F201 -> 112.24 | D7: =[32]Durées!G201 -> 114.38667 | E7: =[32]Durées!H201 -> 115.97 | F7: =[32]Durées!I201 -> 117.988 | G7: =[32]Durées!J201 -> 120.164 | H7: =[32]Durées!K201 -> 122.032 | I7: =[32]Durées!L201 -> 124.184 | J7: =[32]Durées!M201 -> 126.798 | ... BR7: =[32]Durées!BU201 -> 162.27
B8: 1 ou 2 enfants hors MDA | C8: =[32]Durées!F203 -> 105.28 | D8: =[32]Durées!G203 -> 104.34667 | E8: =[32]Durées!H203 -> 105.61 | F8: =[32]Durées!I203 -> 106.644 | G8: =[32]Durées!J203 -> 108.526 | H8: =[32]Durées!K203 -> 110.49 | I8: =[32]Durées!L203 -> 112.748 | J8: =[32]Durées!M203 -> 115.088 | ... BR8: =[32]Durées!BU203 -> 147.75
B9: 3 enfants et plus hors MDA | C9: =[32]Durées!F204 -> 84.95 | D9: =[32]Durées!G204 -> 86.483333 | E9: =[32]Durées!H204 -> 88.112 | F9: =[32]Durées!I204 -> 90.126 | G9: =[32]Durées!J204 -> 92.362 | H9: =[32]Durées!K204 -> 94.244 | I9: =[32]Durées!L204 -> 96.402 | J9: =[32]Durées!M204 -> 99.146 | ... BR9: =[32]Durées!BU204 -> 138.46
B11: Note : ensemble des trimestres validés au titre de la MDA, que ces derniers soient utiles ou non au moment du départ à la retraite.
B12: Champ : ensemble des retraités de droit direct résidant en France et à l’étranger, pondérés pour être représentatifs des assurés ayant perçu une pension.
B13: Source : DREES, EIR 2020.

Sheet Fig A.4
A1: Figure A.4 - Durées d’assurance avec et sans MDA selon le nombre d’enfants pour les femmes retraitées du SRE, par génération
A2: Retour au sommaire
C4: 1945 | D4: 1946 | E4: 1947 | F4: 1948 | G4: 1949 | H4: 1950 | I4: 1951 | J4: 1952 | K4: 1953 | L4: 1954 | M4: 1955 | N4: 1956 | O4: 1957 | P4: 1958 | Q4: 1959 | R4: 1960 | S4: 1961 | T4: 1962 | U4: 1963 | V4: 1964 | W4: 1965 | X4: 1966 | Y4: 1967 | Z4: 1968 | AA4: 1969 | AB4: 1970 | AC4: 1971 | AD4: 1972 | AE4: 1973 | AF4: 1974 | AG4: 1975 | AH4: 1976 | AI4: 1977 | AJ4: 1978 | AK4: 1979 | AL4: 1980 | AM4: 1981 | AN4: 1982 | AO4: 1983 | AP4: 1984 | AQ4: 1985 | AR4: 1986 | AS4: 1987 | AT4: 1988 | AU4: 1989 | AV4: 1990 | AW4: 1991 | AX4: 1992 | AY4: 1993 | AZ4: 1994 | BA4: 1995 | BB4: 1996 | BC4: 1997 | BD4: 1998 | BE4: 1999 | BF4: 2000
B5: Non bénéficiaires de la MDA | C5: =[33]Durées!R159 -> 148.77943 | D5: =[33]Durées!S159 -> 153.73077 | E5: =[33]Durées!T159 -> 155.97902 | F5: =[33]Durées!U159 -> 157.71143 | G5: =[33]Durées!V159 -> 158.68862 | H5: =[33]Durées!W159 -> 159.44181 | I5: =[33]Durées!X159 -> 159.47495 | J5: =[33]Durées!Y159 -> 160.49326 | ... BF5: =[33]Durées!BU159 -> 160.83254
B6: 1 ou 2 enfants y compris MDA | C6: =[33]Durées!R160 -> 152.02483 | D6: =[33]Durées!S160 -> 155.00881 | E6: =[33]Durées!T160 -> 157.09274 | F6: =[33]Durées!U160 -> 159.23256 | G6: =[33]Durées!V160 -> 161.16557 | H6: =[33]Durées!W160 -> 162.89575 | I6: =[33]Durées!X160 -> 164.90724 | J6: =[33]Durées!Y160 -> 166.56665 | ... BF6: =[33]Durées!BU160 -> 169.6098
B7: 3 enfants et plus y compris MDA | C7: =[33]Durées!R161 -> 123.27329 | D7: =[33]Durées!S161 -> 127.96535 | E7: =[33]Durées!T161 -> 130.90578 | F7: =[33]Durées!U161 -> 134.1456 | G7: =[33]Durées!V161 -> 136.80264 | H7: =[33]Durées!W161 -> 139.27877 | I7: =[33]Durées!X161 -> 141.95383 | J7: =[33]Durées!Y161 -> 145.30868 | ... BF7: =[33]Durées!BU161 -> 171.27563
B8: 1 ou 2 enfants hors MDA | C8: =[33]Durées!R163 -> 145.50955 | D8: =[33]Durées!S163 -> 148.55313 | E8: =[33]Durées!T163 -> 150.70601 | F8: =[33]Durées!U163 -> 152.9225 | G8: =[33]Durées!V163 -> 154.91066 | H8: =[33]Durées!W163 -> 156.70798 | I8: =[33]Durées!X163 -> 158.76888 | J8: =[33]Durées!Y163 -> 160.4474 | ... BF8: =[33]Durées!BU163 -> 166.22011
B9: 3 enfants et plus hors MDA | C9: =[33]Durées!R164 -> 112.06438 | D9: =[33]Durées!S164 -> 116.82385 | E9: =[33]Durées!T164 -> 119.92984 | F9: =[33]Durées!U164 -> 123.3434 | G9: =[33]Durées!V164 -> 126.16081 | H9: =[33]Durées!W164 -> 128.67392 | I9: =[33]Durées!X164 -> 131.35966 | J9: =[33]Durées!Y164 -> 134.63079 | ... BF9: =[33]Durées!BU164 -> 164.57401
B11: Note : ensemble des trimestres validés au titre de la MDA, que ces derniers soient utiles ou non au moment du départ à la retraite.
B12: Champ : ensemble des retraités de droit direct résidant en France et à l’étranger, pondérés pour être représentatifs des assurés ayant perçu une pension.
B13: Source : DREES, EIR 2020.

Sheet Fig A.5
A1: Figure A.5 - Part des retraitées de droit propre bénéficiaires de l’AVPF par génération et nombre moyen de trimestres validés à ce titre – Cnav
A2: Retour au sommaire
C4: 1930 | D4: 1931 | E4: 1932 | F4: 1933 | G4: 1934 | H4: 1935 | I4: 1936 | J4: 1937 | K4: 1938 | L4: 1939 | M4: 1940 | N4: 1941 | O4: 1942 | P4: 1943 | Q4: 1944 | R4: 1945 | S4: 1946 | T4: 1947 | U4: 1948 | V4: 1949 | W4: 1950 | X4: 1951 | Y4: 1952 | Z4: 1953 | AA4: 1954 | AB4: 1955 | AC4: 1956 | AD4: 1957 | AE4: 1958 | AF4: 1959 | AG4: 1960 | AH4: 1961 | AI4: 1962 | AJ4: 1963 | AK4: 1964 | AL4: 1965 | AM4: 1966 | AN4: 1967 | AO4: 1968 | AP4: 1969 | AQ4: 1970 | AR4: 1971 | AS4: 1972 | AT4: 1973 | AU4: 1974 | AV4: 1975 | AW4: 1976 | AX4: 1977 | AY4: 1978 | AZ4: 1979 | BA4: 1980 | BB4: 1981 | BC4: 1982 | BD4: 1983 | BE4: 1984 | BF4: 1985 | BG4: 1986 | BH4: 1987 | BI4: 1988 | BJ4: 1989 | BK4: 1990 | BL4: 1991 | BM4: 1992 | BN4: 1993 | BO4: 1994 | BP4: 1995 | BQ4: 1996 | BR4: 1997 | BS4: 1998 | BT4: 1999 | BU4: 2000
B5: Part des bénéficiaires | F5: =[32]Effectifs!E17 -> 0.18866744 | G5: =[32]Effectifs!F17 -> 0.21845886 | H5: =[32]Effectifs!G17 -> 0.2382462 | I5: =[32]Effectifs!H17 -> 0.26044658 | J5: =[32]Effectifs!I17 -> 0.27745345 | K5: =[32]Effectifs!J17 -> 0.29608192 | L5: =[32]Effectifs!K17 -> 0.31108359 | M5: =[32]Effectifs!L17 -> 0.32201447 | ... BU5: =[32]Effectifs!BT17 -> 0.53399593
B6: Nombre moyen de trimestres validés | F6: =[32]Durées!F74 -> 22.20839 | G6: =[32]Durées!G74 -> 22.952618 | H6: =[32]Durées!H74 -> 23.830078 | I6: =[32]Durées!I74 -> 24.620833 | J6: =[32]Durées!J74 -> 25.42548 | K6: =[32]Durées!K74 -> 26.143596 | L6: =[32]Durées!L74 -> 26.698001 | M6: =[32]Durées!M74 -> 27.180436 | ... BU6: =[32]Durées!BU74 -> 21.910279
B8: Champ : ensemble des femmes retraitées de droit direct.
B9: Source : Cnav modèle Prisme.
C12: Part des bénéficiaires | I12: Nombre moyen de trimestres validés

Sheet Fig A.6
A1: Figure A.6 - Part des retraités de droit propre bénéficiaires de la majoration de pension pour trois enfants et plus, par génération et régime
A2: Retour au sommaire
C4: 1930 | D4: 1931 | E4: 1932 | F4: 1933 | G4: 1934 | H4: 1935 | I4: 1936 | J4: 1937 | K4: 1938 | L4: 1939 | M4: 1940 | N4: 1941 | O4: 1942 | P4: 1943 | Q4: 1944 | R4: 1945 | S4: 1946 | T4: 1947 | U4: 1948 | V4: 1949 | W4: 1950 | X4: 1951 | Y4: 1952 | Z4: 1953 | AA4: 1954 | AB4: 1955 | AC4: 1956 | AD4: 1957 | AE4: 1958 | AF4: 1959 | AG4: 1960 | AH4: 1961 | AI4: 1962 | AJ4: 1963 | AK4: 1964 | AL4: 1965 | AM4: 1966 | AN4: 1967 | AO4: 1968 | AP4: 1969 | AQ4: 1970 | AR4: 1971 | AS4: 1972 | AT4: 1973 | AU4: 1974 | AV4: 1975 | AW4: 1976 | AX4: 1977 | AY4: 1978 | AZ4: 1979 | BA4: 1980 | BB4: 1981 | BC4: 1982 | BD4: 1983 | BE4: 1984 | BF4: 1985 | BG4: 1986 | BH4: 1987 | BI4: 1988 | BJ4: 1989 | BK4: 1990 | BL4: 1991 | BM4: 1992 | BN4: 1993 | BO4: 1994 | BP4: 1995 | BQ4: 1996 | BR4: 1997 | BS4: 1998 | BT4: 1999 | BU4: 2000
B5: Cnav | F5: =[32]Effectifs!E35 -> 0.47300713 | G5: =[32]Effectifs!F35 -> 0.47336891 | H5: =[32]Effectifs!G35 -> 0.47060482 | I5: =[32]Effectifs!H35 -> 0.46842736 | J5: =[32]Effectifs!I35 -> 0.46391043 | K5: =[32]Effectifs!J35 -> 0.45961752 | L5: =[32]Effectifs!K35 -> 0.45228469 | M5: =[32]Effectifs!L35 -> 0.44464607 | ... BU5: =[32]Effectifs!BT35 -> 0.25505823
B6: SRE - civils | R6: =[33]Effectifs!Q18 -> 0.23187415 | S6: =[33]Effectifs!R18 -> 0.22583131 | T6: =[33]Effectifs!S18 -> 0.22450805 | U6: =[33]Effectifs!T18 -> 0.22364754 | V6: =[33]Effectifs!U18 -> 0.22854451 | W6: =[33]Effectifs!V18 -> 0.23046745 | X6: =[33]Effectifs!W18 -> 0.23828947 | Y6: =[33]Effectifs!X18 -> 0.24553408 | ... BU6: =[33]Effectifs!BT18 -> 0.20104212
B7: CNRACL | C7: =[34]Effectifs!B41 -> 0.38379499 | D7: =[34]Effectifs!C41 -> 0.38477662 | E7: =[34]Effectifs!D41 -> 0.38079164 | F7: =[34]Effectifs!E41 -> 0.37963764 | G7: =[34]Effectifs!F41 -> 0.37819553 | H7: =[34]Effectifs!G41 -> 0.37649299 | I7: =[34]Effectifs!H41 -> 0.37391693 | J7: =[34]Effectifs!I41 -> 0.37287827 | ... BU7: =[34]Effectifs!BT41 -> 0.30198364
B8: Agirc-Arrco | N8: =[36]Effectifs!M20 -> 0.38406946 | O8: =[36]Effectifs!N20 -> 0.37781814 | P8: =[36]Effectifs!O20 -> 0.37250109 | Q8: =[36]Effectifs!P20 -> 0.36554833 | R8: =[36]Effectifs!Q20 -> 0.35887709 | S8: =[36]Effectifs!R20 -> 0.3537192 | T8: =[36]Effectifs!S20 -> 0.34812218 | U8: =[36]Effectifs!T20 -> 0.34409997 | ... BU8: =[36]Effectifs!BT20 -> 0.31367308
B10: Note : les données CNRACL sont en cours de consolidation.
B11: Champ : ensemble des retraités de droit direct.
B12: Source : Cnav modèle Prisme, SRE modèle Pablo, CNRACL modèle Canopée, Agirc-Arrco modèle Misraa

Sheet Fig A.7
A1: Figure A.7 - Part des bénéficiaires des départs anticipés pour 3 enfants et âge moyen de départ, par génération
A2: Retour au sommaire
D5: 1930 | E5: 1931 | F5: 1932 | G5: 1933 | H5: 1934 | I5: 1935 | J5: 1936 | K5: 1937 | L5: 1938 | M5: 1939 | N5: 1940 | O5: 1941 | P5: 1942 | Q5: 1943 | R5: 1944 | S5: 1945 | T5: 1946 | U5: 1947 | V5: 1948 | W5: 1949 | X5: 1950 | Y5: 1951 | Z5: 1952 | AA5: 1953
B6: Part des bénéficiaires | C6: Ensemble | D6: =[35]Effectifs!B51 -> 0.0065857077 | E6: =[35]Effectifs!C51 -> 0.0058623984 | F6: =[35]Effectifs!D51 -> 0.0053336832 | G6: =[35]Effectifs!E51 -> 0.0075696951 | H6: =[35]Effectifs!F51 -> 0.0069434848 | I6: =[35]Effectifs!G51 -> 0.0087704651 | J6: =[35]Effectifs!H51 -> 0.0082261917 | K6: =[35]Effectifs!I51 -> 0.010883094 | ... AA6: =[35]Effectifs!Y51 -> 0.014789405
C7: Femme | D7: =[35]Effectifs!B52 -> 0.013787169 | E7: =[35]Effectifs!C52 -> 0.012384127 | F7: =[35]Effectifs!D52 -> 0.011320686 | G7: =[35]Effectifs!E52 -> 0.016142091 | H7: =[35]Effectifs!F52 -> 0.014740239 | I7: =[35]Effectifs!G52 -> 0.018529269 | J7: =[35]Effectifs!H52 -> 0.017233085 | K7: =[35]Effectifs!I52 -> 0.022860941 | ... AA7: =[35]Effectifs!Y52 -> 0.027688789
C8: Homme | D8: =[35]Effectifs!B53 -> 0 | E8: =[35]Effectifs!C53 -> 0 | F8: =[35]Effectifs!D53 -> 0 | G8: =[35]Effectifs!E53 -> 0 | H8: =[35]Effectifs!F53 -> 0 | I8: =[35]Effectifs!G53 -> 0 | J8: =[35]Effectifs!H53 -> 0 | K8: =[35]Effectifs!I53 -> 0 | ... AA8: =[35]Effectifs!Y53 -> 0.0015669557
B9: Âge moyen | C9: Femme | D9: =[35]Effectifs!B62 -> 53.777075 | E9: =[35]Effectifs!C62 -> 53.039757 | F9: =[35]Effectifs!D62 -> 52.208862 | G9: =[35]Effectifs!E62 -> 52.300196 | H9: =[35]Effectifs!F62 -> 51.232239 | I9: =[35]Effectifs!G62 -> 51.462142 | J9: =[35]Effectifs!H62 -> 51.033906 | K9: =[35]Effectifs!I62 -> 52.205104 | ... AA9: =[35]Effectifs!Y62 -> 54.996218
B11: Champ : ensemble des retraités de droit direct résidant en France et à l’étranger, pondérés pour être représentatifs des assurés ayant perçu une pension.
B12: Source : DREES, EIR 2020.

Sheet Fig A.8
A1: Figure A.8 - Part des bénéficiaires des départs anticipés pour 3 enfants et âge moyen de départ, par génération et par régime
A2: Retour au sommaire
D5: 1930 | E5: 1931 | F5: 1932 | G5: 1933 | H5: 1934 | I5: 1935 | J5: 1936 | K5: 1937 | L5: 1938 | M5: 1939 | N5: 1940 | O5: 1941 | P5: 1942 | Q5: 1943 | R5: 1944 | S5: 1945 | T5: 1946 | U5: 1947 | V5: 1948 | W5: 1949 | X5: 1950 | Y5: 1951 | Z5: 1952 | AA5: 1953 | AB5: 1954 | AC5: 1955 | AD5: 1956 | AE5: 1957 | AF5: 1958 | AG5: 1959 | AH5: 1960 | AI5: 1961 | AJ5: 1962 | AK5: 1963 | AL5: 1964 | AM5: 1965 | AN5: 1966 | AO5: 1967 | AP5: 1968 | AQ5: 1969 | AR5: 1970 | AS5: 1971 | AT5: 1972 | AU5: 1973 | AV5: 1974 | AW5: 1975
B6: CNRACL | C6: =[34]Effectifs!A49 -> Ensemble | D6: =[34]Effectifs!B49 -> 0.098948304 | E6: =[34]Effectifs!C49 -> 0.1078111 | F6: =[34]Effectifs!D49 -> 0.11307094 | G6: =[34]Effectifs!E49 -> 0.11749088 | H6: =[34]Effectifs!F49 -> 0.12007048 | I6: =[34]Effectifs!G49 -> 0.12185431 | J6: =[34]Effectifs!H49 -> 0.12248232 | ... AW6: =[34]Effectifs!AU49 -> 0.001923473
C7: =[34]Effectifs!A50 -> Femmes | D7: =[34]Effectifs!B50 -> 0.13998324 | E7: =[34]Effectifs!C50 -> 0.15428255 | F7: =[34]Effectifs!D50 -> 0.1619452 | G7: =[34]Effectifs!E50 -> 0.16958231 | H7: =[34]Effectifs!F50 -> 0.17424271 | I7: =[34]Effectifs!G50 -> 0.17796878 | J7: =[34]Effectifs!H50 -> 0.18081763 | ... AW7: =[34]Effectifs!AU50 -> 0.0029811115
C8: =[34]Effectifs!A51 -> Hommes | D8: =[34]Effectifs!B51 -> 0 | E8: =[34]Effectifs!C51 -> 0 | F8: =[34]Effectifs!D51 -> 0 | G8: =[34]Effectifs!E51 -> 0 | H8: =[34]Effectifs!F51 -> 0 | I8: =[34]Effectifs!G51 -> 0 | J8: =[34]Effectifs!H51 -> 0 | ... AW8: =[34]Effectifs!AU51 -> 0
C9: Femmes ayant 3 enfants et plus | D9: =[34]Effectifs!B69 -> 0.36724638 | E9: =[34]Effectifs!C69 -> 0.40331087 | F9: =[34]Effectifs!D69 -> 0.42732711 | G9: =[34]Effectifs!E69 -> 0.44802793 | H9: =[34]Effectifs!F69 -> 0.46060935 | I9: =[34]Effectifs!G69 -> 0.4724572 | J9: =[34]Effectifs!H69 -> 0.4827797 | K9: =[34]Effectifs!I69 -> 0.49066702 | ... AW9: =[34]Effectifs!AU69 -> 0.0014913936
B10: SRE | C10: Ensemble | S10: =[33]Effectifs!Q29 -> 0.074213406 | T10: =[33]Effectifs!R29 -> 0.070933736 | U10: =[33]Effectifs!S29 -> 0.070517263 | V10: =[33]Effectifs!T29 -> 0.068403563 | W10: =[33]Effectifs!U29 -> 0.069597863 | X10: =[33]Effectifs!V29 -> 0.072119492 | Y10: =[33]Effectifs!W29 -> 0.073457226 | Z10: =[33]Effectifs!X29 -> 0.075758236 | ... AW10: =[33]Effectifs!AU29 -> 0.0033569407
C11: Femmes | S11: =[33]Effectifs!Q30 -> 0.12855377 | T11: =[33]Effectifs!R30 -> 0.1188542 | U11: =[33]Effectifs!S30 -> 0.11843618 | V11: =[33]Effectifs!T30 -> 0.11498585 | W11: =[33]Effectifs!U30 -> 0.11818661 | X11: =[33]Effectifs!V30 -> 0.12446199 | Y11: =[33]Effectifs!W30 -> 0.12718389 | Z11: =[33]Effectifs!X30 -> 0.13301421 | ... AW11: =[33]Effectifs!AU30 -> 0.0058473232
C12: Hommes | S12: =[33]Effectifs!Q31 -> 0.0068912711 | T12: =[33]Effectifs!R31 -> 0.013080967 | U12: =[33]Effectifs!S31 -> 0.013356038 | V12: =[33]Effectifs!T31 -> 0.013220664 | W12: =[33]Effectifs!U31 -> 0.012045024 | X12: =[33]Effectifs!V31 -> 0.010925324 | Y12: =[33]Effectifs!W31 -> 0.010862633 | Z12: =[33]Effectifs!X31 -> 0.010304674 | ... AW12: =[33]Effectifs!AU31 -> 0
C13: Femmes ayant 3 enfants et plus | S13: =[33]Effectifs!Q49 -> 0.56545961 | T13: =[33]Effectifs!R49 -> 0.54433957 | U13: =[33]Effectifs!S49 -> 0.54516121 | V13: =[33]Effectifs!T49 -> 0.53704854 | W13: =[33]Effectifs!U49 -> 0.53916141 | X13: =[33]Effectifs!V49 -> 0.54998606 | Y13: =[33]Effectifs!W49 -> 0.54789901 | Z13: =[33]Effectifs!X49 -> 0.5427189 | ... AW13: =[33]Effectifs!AU49 -> 0.025668582
B15: Note : les départs anticipés pour 3 enfants et plus n’étant pas projetés, le dispositif étant en extinction depuis 2012, les âges moyens de départ chutent donc fortement au fil des générations.
B16: Champ : ensemble des retraités de droit direct.
B17: Source : CNRACL Canopée, SRE Pablo.
D20: CNRACL | J20: SRE

Sheet Fig A.9
A1: Figure A.9 - Âge moyen de départ à la retraite des femmes bénéficiaires du dispositif et des femmes de 3 enfants et plus, par génération et par régime
A2: Retour au sommaire
D5: 1930 | E5: 1931 | F5: 1932 | G5: 1933 | H5: 1934 | I5: 1935 | J5: 1936 | K5: 1937 | L5: 1938 | M5: 1939 | N5: 1940 | O5: 1941 | P5: 1942 | Q5: 1943 | R5: 1944 | S5: 1945 | T5: 1946 | U5: 1947 | V5: 1948 | W5: 1949 | X5: 1950 | Y5: 1951 | Z5: 1952 | AA5: 1953 | AB5: 1954 | AC5: 1955 | AD5: 1956 | AE5: 1957 | AF5: 1958 | AG5: 1959 | AH5: 1960 | AI5: 1961 | AJ5: 1962 | AK5: 1963 | AL5: 1964 | AM5: 1965 | AN5: 1966 | AO5: 1967 | AP5: 1968 | AQ5: 1969 | AR5: 1970 | AS5: 1971 | AT5: 1972 | AU5: 1973 | AV5: 1974 | AW5: 1975
B6: CNRACL | C6: Femmes bénéficiaires | D6: =[34]Effectifs!B59 -> 55.02 | E6: =[34]Effectifs!C59 -> 54.913333 | F6: =[34]Effectifs!D59 -> 54.676 | G6: =[34]Effectifs!E59 -> 54.476 | H6: =[34]Effectifs!F59 -> 54.246 | I6: =[34]Effectifs!G59 -> 53.936 | J6: =[34]Effectifs!H59 -> 53.678 | K6: =[34]Effectifs!I59 -> 53.44 | ... AW6: =[34]Effectifs!AU59 -> 36.176
C7: Femmes ayant 3 enfants et plus | D7: =[34]Effectifs!B86 -> 58.19 | E7: =[34]Effectifs!C86 -> 57.976667 | F7: =[34]Effectifs!D86 -> 57.722 | G7: =[34]Effectifs!E86 -> 57.49 | H7: =[34]Effectifs!F86 -> 57.264 | I7: =[34]Effectifs!G86 -> 57.024 | J7: =[34]Effectifs!H86 -> 56.798 | K7: =[34]Effectifs!I86 -> 56.6 | ... AW7: =[34]Effectifs!AU86 -> 63.586
B8: SRE | C8: Femmes bénéficiaires | S8: =[33]Effectifs!Q40 -> 51.483974 | T8: =[33]Effectifs!R40 -> 51.427564 | U8: =[33]Effectifs!S40 -> 51.645257 | V8: =[33]Effectifs!T40 -> 51.549427 | W8: =[33]Effectifs!U40 -> 51.722065 | X8: =[33]Effectifs!V40 -> 51.827513 | Y8: =[33]Effectifs!W40 -> 51.763378 | Z8: =[33]Effectifs!X40 -> 51.778476 | ... AW8: =[33]Effectifs!AU40 -> 56.375
C9: Femmes ayant 3 enfants et plus | S9: =[33]Effectifs!Q69 -> 55.447075 | T9: =[33]Effectifs!R69 -> 55.584632 | U9: =[33]Effectifs!S69 -> 55.734232 | V9: =[33]Effectifs!T69 -> 55.771753 | W9: =[33]Effectifs!U69 -> 55.907109 | X9: =[33]Effectifs!V69 -> 55.962104 | Y9: =[33]Effectifs!W69 -> 56.094319 | Z9: =[33]Effectifs!X69 -> 56.24987 | ... BV9: =[33]Effectifs!BT69 -> 65.659946
B11: Champ : ensemble des femmes retraitées de droit direct.
B12: Source : CNRACL Canopée, SRE Pablo.
D16: CNRACL | J16: SRE

Sheet Tab B.1
A1: Tableau B.1 - Attribution de 8 trimestres de MDA quel que soit le régime d’affiliation - génération 2000
A2: Retour au sommaire
D4: ='[37]TABLEAU FINAL'!D3 -> Nombre d'enfants | E4: ='[37]TABLEAU FINAL'!E3 -> Durée validée totale moyenne (écart en trimestres) | F4: ='[37]TABLEAU FINAL'!F3 -> Âge de départ (écart en année) | G4: ='[37]TABLEAU FINAL'!G3 -> Pension moyenne 68 ans | H4: ='[37]TABLEAU FINAL'!H3 -> Pension moyenne CV
B5: ='[37]TABLEAU FINAL'!B4 -> Femmes | C5: ='[37]TABLEAU FINAL'!C4 -> 0 | D5: ='[37]TABLEAU FINAL'!D4 -> Ensemble | E5: ='[37]TABLEAU FINAL'!E4 -> 1.6629517 | F5: ='[37]TABLEAU FINAL'!F4 -> -0.072031768 | G5: ='[37]TABLEAU FINAL'!G4 -> 0.018508938 | H5: ='[37]TABLEAU FINAL'!H4 -> 0.022372717
B6: ='[37]TABLEAU FINAL'!B5 -> Hommes | C6: ='[37]TABLEAU FINAL'!C5 -> 0 | D6: ='[37]TABLEAU FINAL'!D5 -> Ensemble | E6: ='[37]TABLEAU FINAL'!E5 -> - | F6: ='[37]TABLEAU FINAL'!F5 -> - | G6: ='[37]TABLEAU FINAL'!G5 -> - | H6: ='[37]TABLEAU FINAL'!H5 -> -
B7: ='[37]TABLEAU FINAL'!B6 -> Selon le nombre d'enfants | C7: ='[37]TABLEAU FINAL'!C6 -> 0 | D7: ='[37]TABLEAU FINAL'!D6 -> 0 | E7: ='[37]TABLEAU FINAL'!E6 -> 0 | F7: ='[37]TABLEAU FINAL'!F6 -> 0 | G7: ='[37]TABLEAU FINAL'!G6 -> 0 | H7: ='[37]TABLEAU FINAL'!H6 -> 0
B8: ='[37]TABLEAU FINAL'!B7 -> Femmes | C8: ='[37]TABLEAU FINAL'!C7 -> 0 | D8: ='[37]TABLEAU FINAL'!D7 -> 1 | E8: ='[37]TABLEAU FINAL'!E7 -> 0.91632683 | F8: ='[37]TABLEAU FINAL'!F7 -> -0.062017201 | G8: ='[37]TABLEAU FINAL'!G7 -> 0.010426101 | H8: ='[37]TABLEAU FINAL'!H7 -> 0.013025468
B9: ='[37]TABLEAU FINAL'!B8 -> 0 | C9: ='[37]TABLEAU FINAL'!C8 -> 0 | D9: ='[37]TABLEAU FINAL'!D8 -> 2 | E9: ='[37]TABLEAU FINAL'!E8 -> 1.7678096 | F9: ='[37]TABLEAU FINAL'!F8 -> -0.086990669 | G9: ='[37]TABLEAU FINAL'!G8 -> 0.021782489 | H9: ='[37]TABLEAU FINAL'!H8 -> 0.0265928
B10: ='[37]TABLEAU FINAL'!B9 -> 0 | C10: ='[37]TABLEAU FINAL'!C9 -> 0 | D10: ='[37]TABLEAU FINAL'!D9 -> 3 et plus | E10: ='[37]TABLEAU FINAL'!E9 -> 2.691802 | F10: ='[37]TABLEAU FINAL'!F9 -> -0.086962556 | G10: ='[37]TABLEAU FINAL'!G9 -> 0.026678632 | H10: ='[37]TABLEAU FINAL'!H9 -> 0.031381183
B11: ='[37]TABLEAU FINAL'!B10 -> Selon le régime d'affiliation | C11: ='[37]TABLEAU FINAL'!C10 -> 0 | D11: ='[37]TABLEAU FINAL'!D10 -> 0 | E11: ='[37]TABLEAU FINAL'!E10 -> 0 | F11: ='[37]TABLEAU FINAL'!F10 -> 0 | G11: ='[37]TABLEAU FINAL'!G10 -> 0 | H11: ='[37]TABLEAU FINAL'!H10 -> 0
B12: ='[37]TABLEAU FINAL'!B11 -> Femmes | C12: ='[37]TABLEAU FINAL'!C11 -> Mono Lura | D12: ='[37]TABLEAU FINAL'!D11 -> 1 | E12: ='[37]TABLEAU FINAL'!E11 -> 0.16441557 | F12: ='[37]TABLEAU FINAL'!F11 -> -0.0049246797 | G12: ='[37]TABLEAU FINAL'!G11 -> 0.0010773237 | H12: ='[37]TABLEAU FINAL'!H11 -> 0.0013842068
B13: ='[37]TABLEAU FINAL'!B12 -> 0 | C13: ='[37]TABLEAU FINAL'!C12 -> 0 | D13: ='[37]TABLEAU FINAL'!D12 -> 2 | E13: ='[37]TABLEAU FINAL'!E12 -> 0.24282098 | F13: ='[37]TABLEAU FINAL'!F12 -> -0.0076229664 | G13: ='[37]TABLEAU FINAL'!G12 -> 0.0042042481 | H13: ='[37]TABLEAU FINAL'!H12 -> 0.0049275215
B14: ='[37]TABLEAU FINAL'!B13 -> 0 | C14: ='[37]TABLEAU FINAL'!C13 -> 0 | D14: ='[37]TABLEAU FINAL'!D13 -> 3 et plus | E14: ='[37]TABLEAU FINAL'!E13 -> 0.38022982 | F14: ='[37]TABLEAU FINAL'!F13 -> -0.008227277 | G14: ='[37]TABLEAU FINAL'!G13 -> 0.0039413672 | H14: ='[37]TABLEAU FINAL'!H13 -> 0.0041786849
B15: ='[37]TABLEAU FINAL'!B14 -> 0 | C15: ='[37]TABLEAU FINAL'!C14 -> Mono FP-RS | D15: ='[37]TABLEAU FINAL'!D14 -> 1 | E15: ='[37]TABLEAU FINAL'!E14 -> 2.964156 | F15: ='[37]TABLEAU FINAL'!F14 -> -0.2633769 | G15: ='[37]TABLEAU FINAL'!G14 -> 0.0070405742 | H15: ='[37]TABLEAU FINAL'!H14 -> 0.013588034
B16: ='[37]TABLEAU FINAL'!B15 -> 0 | C16: ='[37]TABLEAU FINAL'!C15 -> 0 | D16: ='[37]TABLEAU FINAL'!D15 -> 2 | E16: ='[37]TABLEAU FINAL'!E15 -> 7.1636578 | F16: ='[37]TABLEAU FINAL'!F15 -> -0.36166655 | G16: ='[37]TABLEAU FINAL'!G15 -> 0.066973278 | H16: ='[37]TABLEAU FINAL'!H15 -> 0.081656287
... B42: ='[37]TABLEAU FINAL'!B41 -> 0 | C42: ='[37]TABLEAU FINAL'!C41 -> 0 | D42: ='[37]TABLEAU FINAL'!D41 -> 3 et plus | E42: ='[37]TABLEAU FINAL'!E41 -> 3.0485071 | F42: ='[37]TABLEAU FINAL'!F41 -> -0.11910904 | G42: ='[37]TABLEAU FINAL'!G41 -> 0.02172666 | H42: ='[37]TABLEAU FINAL'!H41 -> 0.027348193
B44: Source : Drees – modèle Trajectoire

Sheet Tab B.2
A1: Tableau B.2 - Attribution de 4 trimestres de MDA quel que soit le régime d’affiliation - génération 2000
A2: Retour au sommaire
D4: ='[38]TABLEAU FINAL'!D3 -> Nombre d'enfants | E4: ='[38]TABLEAU FINAL'!E3 -> Durée validée totale moyenne (écart en trimestres) | F4: ='[38]TABLEAU FINAL'!F3 -> Âge de départ (écart en année) | G4: ='[38]TABLEAU FINAL'!G3 -> Pension moyenne 68 ans | H4: ='[38]TABLEAU FINAL'!H3 -> Pension moyenne CV
B5: ='[38]TABLEAU FINAL'!B4 -> Femmes | D5: ='[38]TABLEAU FINAL'!D4 -> Ensemble | E5: ='[38]TABLEAU FINAL'!E4 -> -3.2193994 | F5: ='[38]TABLEAU FINAL'!F4 -> 0.040092886 | G5: ='[38]TABLEAU FINAL'!G4 -> 0.0014382383 | H5: ='[38]TABLEAU FINAL'!H4 -> 0.00053577657
B6: ='[38]TABLEAU FINAL'!B5 -> Hommes | D6: ='[38]TABLEAU FINAL'!D5 -> Ensemble | E6: ='[38]TABLEAU FINAL'!E5 -> - | F6: ='[38]TABLEAU FINAL'!F5 -> - | G6: ='[38]TABLEAU FINAL'!G5 -> - | H6: ='[38]TABLEAU FINAL'!H5 -> -
B7: ='[38]TABLEAU FINAL'!B6 -> Selon le nombre d'enfants
B8: ='[38]TABLEAU FINAL'!B7 -> Femmes | D8: ='[38]TABLEAU FINAL'!D7 -> 1 | E8: ='[38]TABLEAU FINAL'!E7 -> -1.5721505 | F8: ='[38]TABLEAU FINAL'!F7 -> 0.046663418 | G8: ='[38]TABLEAU FINAL'!G7 -> -0.0019066394 | H8: ='[38]TABLEAU FINAL'!H7 -> -0.0039939413
D9: ='[38]TABLEAU FINAL'!D8 -> 2 | E9: ='[38]TABLEAU FINAL'!E8 -> -3.340057 | F9: ='[38]TABLEAU FINAL'!F8 -> 0.045935244 | G9: ='[38]TABLEAU FINAL'!G8 -> 0.0023283348 | H9: ='[38]TABLEAU FINAL'!H8 -> 0.001193254
D10: ='[38]TABLEAU FINAL'!D9 -> 3 et plus | E10: ='[38]TABLEAU FINAL'!E9 -> -5.4445146 | F10: ='[38]TABLEAU FINAL'!F9 -> 0.043330573 | G10: ='[38]TABLEAU FINAL'!G9 -> 0.0029902597 | H10: ='[38]TABLEAU FINAL'!H9 -> 0.0028072361
B11: ='[38]TABLEAU FINAL'!B10 -> Selon le régime d'affiliation
B12: ='[38]TABLEAU FINAL'!B11 -> Femmes | C12: ='[38]TABLEAU FINAL'!C11 -> Mono Lura | D12: ='[38]TABLEAU FINAL'!D11 -> 1 | E12: ='[38]TABLEAU FINAL'!E11 -> -2.3907319 | F12: ='[38]TABLEAU FINAL'!F11 -> 0.087462958 | G12: ='[38]TABLEAU FINAL'!G11 -> -0.0076424049 | H12: ='[38]TABLEAU FINAL'!H11 -> -0.011381783
D13: ='[38]TABLEAU FINAL'!D12 -> 2 | E13: ='[38]TABLEAU FINAL'!E12 -> -4.9273812 | F13: ='[38]TABLEAU FINAL'!F12 -> 0.098631464 | G13: ='[38]TABLEAU FINAL'!G12 -> -0.010849796 | H13: ='[38]TABLEAU FINAL'!H12 -> -0.014843465
D14: ='[38]TABLEAU FINAL'!D13 -> 3 et plus | E14: ='[38]TABLEAU FINAL'!E13 -> -7.8961484 | F14: ='[38]TABLEAU FINAL'!F13 -> 0.10050374 | G14: ='[38]TABLEAU FINAL'!G13 -> -0.012144612 | H14: ='[38]TABLEAU FINAL'!H13 -> -0.015113618
C15: ='[38]TABLEAU FINAL'!C14 -> Mono FP-RS | D15: ='[38]TABLEAU FINAL'!D14 -> 1 | E15: ='[38]TABLEAU FINAL'!E14 -> 0.87455064 | F15: ='[38]TABLEAU FINAL'!F14 -> -0.11528315 | G15: ='[38]TABLEAU FINAL'!G14 -> -0.0078911146 | H15: ='[38]TABLEAU FINAL'!H14 -> -0.0074671881
D16: ='[38]TABLEAU FINAL'!D15 -> 2 | E16: ='[38]TABLEAU FINAL'!E15 -> 2.0027254 | F16: ='[38]TABLEAU FINAL'!F15 -> -0.17035198 | G16: ='[38]TABLEAU FINAL'!G15 -> 0.036234158 | H16: ='[38]TABLEAU FINAL'!H15 -> 0.043534513
D17: ='[38]TABLEAU FINAL'!D16 -> 3 et plus | E17: ='[38]TABLEAU FINAL'!E16 -> 3.5725269 | F17: ='[38]TABLEAU FINAL'!F16 -> -0.18774326 | G17: ='[38]TABLEAU FINAL'!G16 -> 0.042887956 | H17: ='[38]TABLEAU FINAL'!H16 -> 0.052698183
C18: ='[38]TABLEAU FINAL'!C17 -> Mono MSAE-PLIB | D18: ='[38]TABLEAU FINAL'!D17 -> 1 | E18: ='[38]TABLEAU FINAL'!E17 -> -3.2430301 | F18: ='[38]TABLEAU FINAL'!F17 -> 0.020135903 | G18: ='[38]TABLEAU FINAL'!G17 -> 0.0023728178 | H18: ='[38]TABLEAU FINAL'!H17 -> -0.0010036242
D19: ='[38]TABLEAU FINAL'!D18 -> 2 | E19: ='[38]TABLEAU FINAL'!E18 -> -0.1061263 | F19: ='[38]TABLEAU FINAL'!F18 -> 0.03551817 | G19: ='[38]TABLEAU FINAL'!G18 -> 0.030685541 | H19: ='[38]TABLEAU FINAL'!H18 -> 0.028178493
D20: ='[38]TABLEAU FINAL'!D19 -> 3 et plus | E20: ='[38]TABLEAU FINAL'!E19 -> n.a | F20: ='[38]TABLEAU FINAL'!F19 -> n.a | G20: ='[38]TABLEAU FINAL'!G19 -> n.a | H20: ='[38]TABLEAU FINAL'!H19 -> n.a
C21: ='[38]TABLEAU FINAL'!C20 -> Poly Lura-FP-RS | D21: ='[38]TABLEAU FINAL'!D20 -> 1 | E21: ='[38]TABLEAU FINAL'!E20 -> 1.1269076 | F21: ='[38]TABLEAU FINAL'!F20 -> -0.075788915 | G21: ='[38]TABLEAU FINAL'!G20 -> 0.017562822 | H21: ='[38]TABLEAU FINAL'!H20 -> 0.021361389
D22: ='[38]TABLEAU FINAL'!D21 -> 2 | E22: ='[38]TABLEAU FINAL'!E21 -> 2.1650622 | F22: ='[38]TABLEAU FINAL'!F21 -> -0.13821047 | G22: ='[38]TABLEAU FINAL'!G21 -> 0.036321364 | H22: ='[38]TABLEAU FINAL'!H21 -> 0.042114793
D23: ='[38]TABLEAU FINAL'!D22 -> 3 et plus | E23: ='[38]TABLEAU FINAL'!E22 -> 3.2320339 | F23: ='[38]TABLEAU FINAL'!F22 -> -0.16684706 | G23: ='[38]TABLEAU FINAL'!G22 -> 0.047626755 | H23: ='[38]TABLEAU FINAL'!H22 -> 0.053749357
C24: ='[38]TABLEAU FINAL'!C23 -> Poly Lura-MSAE-PLIB | D24: ='[38]TABLEAU FINAL'!D23 -> 1 | E24: ='[38]TABLEAU FINAL'!E23 -> -2.3376937 | F24: ='[38]TABLEAU FINAL'!F23 -> 0.096052549 | G24: ='[38]TABLEAU FINAL'!G23 -> -0.0035945858 | H24: ='[38]TABLEAU FINAL'!H23 -> -0.007482558
D25: ='[38]TABLEAU FINAL'!D24 -> 2 | E25: ='[38]TABLEAU FINAL'!E24 -> -5.0518325 | F25: ='[38]TABLEAU FINAL'!F24 -> 0.13779142 | G25: ='[38]TABLEAU FINAL'!G24 -> -0.0045694404 | H25: ='[38]TABLEAU FINAL'!H24 -> -0.010054008
D26: ='[38]TABLEAU FINAL'!D25 -> 3 et plus | E26: ='[38]TABLEAU FINAL'!E25 -> -6.9086521 | F26: ='[38]TABLEAU FINAL'!F25 -> 0.14657414 | G26: ='[38]TABLEAU FINAL'!G25 -> -0.011323837 | H26: ='[38]TABLEAU FINAL'!H25 -> -0.016577584
B27: ='[38]TABLEAU FINAL'!B26 -> Selon le quintile de pension
B28: ='[38]TABLEAU FINAL'!B27 -> Femmes | C28: ='[38]TABLEAU FINAL'!C27 -> Q1 | D28: ='[38]TABLEAU FINAL'!D27 -> 1 | E28: ='[38]TABLEAU FINAL'!E27 -> -2.274611 | F28: ='[38]TABLEAU FINAL'!F27 -> 0.0044157531 | G28: ='[38]TABLEAU FINAL'!G27 -> -0.018277754 | H28: ='[38]TABLEAU FINAL'!H27 -> -0.016876686
D29: ='[38]TABLEAU FINAL'!D28 -> 2 | E29: ='[38]TABLEAU FINAL'!E28 -> -4.7755668 | F29: ='[38]TABLEAU FINAL'!F28 -> 0.016097849 | G29: ='[38]TABLEAU FINAL'!G28 -> -0.035917467 | H29: ='[38]TABLEAU FINAL'!H28 -> -0.03619775
D30: ='[38]TABLEAU FINAL'!D29 -> 3 et plus | E30: ='[38]TABLEAU FINAL'!E29 -> -7.5988923 | F30: ='[38]TABLEAU FINAL'!F29 -> 0.019298425 | G30: ='[38]TABLEAU FINAL'!G29 -> -0.050084647 | H30: ='[38]TABLEAU FINAL'!H29 -> -0.050529581
C31: ='[38]TABLEAU FINAL'!C30 -> Q2 | D31: ='[38]TABLEAU FINAL'!D30 -> 1 | E31: ='[38]TABLEAU FINAL'!E30 -> -1.49643 | F31: ='[38]TABLEAU FINAL'!F30 -> 0.060025832 | G31: ='[38]TABLEAU FINAL'!G30 -> -0.0019474434 | H31: ='[38]TABLEAU FINAL'!H30 -> -0.0040457353
D32: ='[38]TABLEAU FINAL'!D31 -> 2 | E32: ='[38]TABLEAU FINAL'!E31 -> -3.2592486 | F32: ='[38]TABLEAU FINAL'!F31 -> 0.064486545 | G32: ='[38]TABLEAU FINAL'!G31 -> -0.00038978209 | H32: ='[38]TABLEAU FINAL'!H31 -> -0.0010849018
D33: ='[38]TABLEAU FINAL'!D32 -> 3 et plus | E33: ='[38]TABLEAU FINAL'!E32 -> -6.6369989 | F33: ='[38]TABLEAU FINAL'!F32 -> 0.14046431 | G33: ='[38]TABLEAU FINAL'!G32 -> -0.0083869977 | H33: ='[38]TABLEAU FINAL'!H32 -> -0.012050929
C34: ='[38]TABLEAU FINAL'!C33 -> Q3 | D34: ='[38]TABLEAU FINAL'!D33 -> 1 | E34: ='[38]TABLEAU FINAL'!E33 -> -1.2247643 | F34: ='[38]TABLEAU FINAL'!F33 -> 0.031114847 | G34: ='[38]TABLEAU FINAL'!G33 -> 0.0012806569 | H34: ='[38]TABLEAU FINAL'!H33 -> 0.00023178886
D35: ='[38]TABLEAU FINAL'!D34 -> 2 | E35: ='[38]TABLEAU FINAL'!E34 -> -2.7098904 | F35: ='[38]TABLEAU FINAL'!F34 -> 0.044769875 | G35: ='[38]TABLEAU FINAL'!G34 -> 0.0047227121 | H35: ='[38]TABLEAU FINAL'!H34 -> 0.003247117
D36: ='[38]TABLEAU FINAL'!D35 -> 3 et plus | E36: ='[38]TABLEAU FINAL'!E35 -> -3.6727589 | F36: ='[38]TABLEAU FINAL'!F35 -> -0.00029609863 | G36: ='[38]TABLEAU FINAL'!G35 -> 0.0092088123 | H36: ='[38]TABLEAU FINAL'!H35 -> 0.0089334837
C37: ='[38]TABLEAU FINAL'!C36 -> Q4 | D37: ='[38]TABLEAU FINAL'!D36 -> 1 | E37: ='[38]TABLEAU FINAL'!E36 -> -1.3071192 | F37: ='[38]TABLEAU FINAL'!F36 -> 0.097868882 | G37: ='[38]TABLEAU FINAL'!G36 -> 0.0019823499 | H37: ='[38]TABLEAU FINAL'!H36 -> 0.00018585154
D38: ='[38]TABLEAU FINAL'!D37 -> 2 | E38: ='[38]TABLEAU FINAL'!E37 -> -2.8173751 | F38: ='[38]TABLEAU FINAL'!F37 -> 0.031209161 | G38: ='[38]TABLEAU FINAL'!G37 -> 0.0060406521 | H38: ='[38]TABLEAU FINAL'!H37 -> 0.005665331
D39: ='[38]TABLEAU FINAL'!D38 -> 3 et plus | E39: ='[38]TABLEAU FINAL'!E38 -> -4.717492 | F39: ='[38]TABLEAU FINAL'!F38 -> 0.015897525 | G39: ='[38]TABLEAU FINAL'!G38 -> 0.011150218 | H39: ='[38]TABLEAU FINAL'!H38 -> 0.01146758
C40: ='[38]TABLEAU FINAL'!C39 -> Q5 | D40: ='[38]TABLEAU FINAL'!D39 -> 1 | E40: ='[38]TABLEAU FINAL'!E39 -> -1.68001 | F40: ='[38]TABLEAU FINAL'!F39 -> 0.059235776 | G40: ='[38]TABLEAU FINAL'!G39 -> -0.0042189502 | H40: ='[38]TABLEAU FINAL'!H39 -> -0.0082802321
D41: ='[38]TABLEAU FINAL'!D40 -> 2 | E41: ='[38]TABLEAU FINAL'!E40 -> -3.6607391 | F41: ='[38]TABLEAU FINAL'!F40 -> 0.081290248 | G41: ='[38]TABLEAU FINAL'!G40 -> 0.0044837569 | H41: ='[38]TABLEAU FINAL'!H40 -> 0.0019407448
...

Sheet Tab B.3
A1: Tableau B.3 - Attribution de 2 trimestres de MDA quel que soit le régime d’affiliation - génération 2000
A2: Retour au sommaire
D4: ='[39]TABLEAU FINAL'!D3 -> Nombre d'enfants | E4: ='[39]TABLEAU FINAL'!E3 -> Durée validée totale moyenne (écart en trimestres) | F4: ='[39]TABLEAU FINAL'!F3 -> Âge de départ (écart en année) | G4: ='[39]TABLEAU FINAL'!G3 -> Pension moyenne 68 ans | H4: ='[39]TABLEAU FINAL'!H3 -> Pension moyenne CV
B5: ='[39]TABLEAU FINAL'!B4 -> Femmes | D5: ='[39]TABLEAU FINAL'!D4 -> Ensemble | E5: ='[39]TABLEAU FINAL'!E4 -> -5.5213751 | F5: ='[39]TABLEAU FINAL'!F4 -> 0.11817101 | G5: ='[39]TABLEAU FINAL'!G4 -> -0.0070513834 | H5: ='[39]TABLEAU FINAL'!H4 -> -0.011387155
B6: ='[39]TABLEAU FINAL'!B5 -> Hommes | D6: ='[39]TABLEAU FINAL'!D5 -> Ensemble | E6: ='[39]TABLEAU FINAL'!E5 -> - | F6: ='[39]TABLEAU FINAL'!F5 -> - | G6: ='[39]TABLEAU FINAL'!G5 -> - | H6: ='[39]TABLEAU FINAL'!H5 -> -
B7: ='[39]TABLEAU FINAL'!B6 -> Selon le nombre d'enfants
B8: ='[39]TABLEAU FINAL'!B7 -> Femmes | D8: ='[39]TABLEAU FINAL'!D7 -> 1 | E8: ='[39]TABLEAU FINAL'!E7 -> -2.6258468 | F8: ='[39]TABLEAU FINAL'!F7 -> 0.11066749 | G8: ='[39]TABLEAU FINAL'!G7 -> -0.0038183988 | H8: ='[39]TABLEAU FINAL'!H7 -> -0.0084938482
D9: ='[39]TABLEAU FINAL'!D8 -> 2 | E9: ='[39]TABLEAU FINAL'!E8 -> -5.7860156 | F9: ='[39]TABLEAU FINAL'!F8 -> 0.13996205 | G9: ='[39]TABLEAU FINAL'!G8 -> -0.0087004551 | H9: ='[39]TABLEAU FINAL'!H8 -> -0.013791026
D10: ='[39]TABLEAU FINAL'!D9 -> 3 et plus | E10: ='[39]TABLEAU FINAL'!E9 -> -9.3169774 | F10: ='[39]TABLEAU FINAL'!F9 -> 0.14016487 | G10: ='[39]TABLEAU FINAL'!G9 -> -0.0097166868 | H10: ='[39]TABLEAU FINAL'!H9 -> -0.014405818
B11: ='[39]TABLEAU FINAL'!B10 -> Selon le régime d'affiliation
B12: ='[39]TABLEAU FINAL'!B11 -> Femmes | C12: ='[39]TABLEAU FINAL'!C11 -> Mono Lura | D12: ='[39]TABLEAU FINAL'!D11 -> 1 | E12: ='[39]TABLEAU FINAL'!E11 -> -3.4088594 | F12: ='[39]TABLEAU FINAL'!F11 -> 0.14829112 | G12: ='[39]TABLEAU FINAL'!G11 -> -0.0087510074 | H12: ='[39]TABLEAU FINAL'!H11 -> -0.015739565
D13: ='[39]TABLEAU FINAL'!D12 -> 2 | E13: ='[39]TABLEAU FINAL'!E12 -> -7.4212427 | F13: ='[39]TABLEAU FINAL'!F12 -> 0.17803443 | G13: ='[39]TABLEAU FINAL'!G12 -> -0.019285696 | H13: ='[39]TABLEAU FINAL'!H12 -> -0.026447824
D14: ='[39]TABLEAU FINAL'!D13 -> 3 et plus | E14: ='[39]TABLEAU FINAL'!E13 -> -11.847611 | F14: ='[39]TABLEAU FINAL'!F13 -> 0.17716738 | G14: ='[39]TABLEAU FINAL'!G13 -> -0.021247031 | H14: ='[39]TABLEAU FINAL'!H13 -> -0.027580375
C15: ='[39]TABLEAU FINAL'!C14 -> Mono FP-RS | D15: ='[39]TABLEAU FINAL'!D14 -> 1 | E15: ='[39]TABLEAU FINAL'!E14 -> -0.050136326 | F15: ='[39]TABLEAU FINAL'!F14 -> 0 | G15: ='[39]TABLEAU FINAL'!G14 -> 0.0072343803 | H15: ='[39]TABLEAU FINAL'!H14 -> 0.007017091
D16: ='[39]TABLEAU FINAL'!D15 -> 2 | E16: ='[39]TABLEAU FINAL'!E15 -> -0.16297612 | F16: ='[39]TABLEAU FINAL'!F15 -> 0.0038463687 | G16: ='[39]TABLEAU FINAL'!G15 -> 0.015805706 | H16: ='[39]TABLEAU FINAL'!H15 -> 0.014849985
D17: ='[39]TABLEAU FINAL'!D16 -> 3 et plus | E17: ='[39]TABLEAU FINAL'!E16 -> -0.21265522 | F17: ='[39]TABLEAU FINAL'!F16 -> 0 | G17: ='[39]TABLEAU FINAL'!G16 -> 0.025034416 | H17: ='[39]TABLEAU FINAL'!H16 -> 0.023983617
C18: ='[39]TABLEAU FINAL'!C17 -> Mono MSAE-PLIB | D18: ='[39]TABLEAU FINAL'!D17 -> 1 | E18: ='[39]TABLEAU FINAL'!E17 -> -5.2269914 | F18: ='[39]TABLEAU FINAL'!F17 -> -0.060407708 | G18: ='[39]TABLEAU FINAL'!G17 -> -0.01255206 | H18: ='[39]TABLEAU FINAL'!H17 -> -0.0022260632
D19: ='[39]TABLEAU FINAL'!D18 -> 2 | E19: ='[39]TABLEAU FINAL'!E18 -> -3.1374999 | F19: ='[39]TABLEAU FINAL'!F18 -> 0 | G19: ='[39]TABLEAU FINAL'!G18 -> 0.021750763 | H19: ='[39]TABLEAU FINAL'!H18 -> 0.023890685
D20: ='[39]TABLEAU FINAL'!D19 -> 3 et plus | E20: ='[39]TABLEAU FINAL'!E19 -> n.a | F20: ='[39]TABLEAU FINAL'!F19 -> n.a | G20: ='[39]TABLEAU FINAL'!G19 -> n.a | H20: ='[39]TABLEAU FINAL'!H19 -> n.a
C21: ='[39]TABLEAU FINAL'!C20 -> Poly Lura-FP-RS | D21: ='[39]TABLEAU FINAL'!D20 -> 1 | E21: ='[39]TABLEAU FINAL'!E20 -> -0.023768542 | F21: ='[39]TABLEAU FINAL'!F20 -> 0 | G21: ='[39]TABLEAU FINAL'!G20 -> 0.0099490073 | H21: ='[39]TABLEAU FINAL'!H20 -> 0.010428075
D22: ='[39]TABLEAU FINAL'!D21 -> 2 | E22: ='[39]TABLEAU FINAL'!E21 -> -0.13989074 | F22: ='[39]TABLEAU FINAL'!F21 -> 0.0027642595 | G22: ='[39]TABLEAU FINAL'!G21 -> 0.016384507 | H22: ='[39]TABLEAU FINAL'!H21 -> 0.016340291
D23: ='[39]TABLEAU FINAL'!D22 -> 3 et plus | E23: ='[39]TABLEAU FINAL'!E22 -> -0.38232125 | F23: ='[39]TABLEAU FINAL'!F22 -> 0.00032776674 | G23: ='[39]TABLEAU FINAL'!G22 -> 0.021458558 | H23: ='[39]TABLEAU FINAL'!H22 -> 0.021148317
C24: ='[39]TABLEAU FINAL'!C23 -> Poly Lura-MSAE-PLIB | D24: ='[39]TABLEAU FINAL'!D23 -> 1 | E24: ='[39]TABLEAU FINAL'!E23 -> -3.8554567 | F24: ='[39]TABLEAU FINAL'!F23 -> 0.11181427 | G24: ='[39]TABLEAU FINAL'!G23 -> -0.012502159 | H24: ='[39]TABLEAU FINAL'!H23 -> -0.015985419
D25: ='[39]TABLEAU FINAL'!D24 -> 2 | E25: ='[39]TABLEAU FINAL'!E24 -> -7.6908263 | F25: ='[39]TABLEAU FINAL'!F24 -> 0.21173764 | G25: ='[39]TABLEAU FINAL'!G24 -> -0.011548343 | H25: ='[39]TABLEAU FINAL'!H24 -> -0.019395449
D26: ='[39]TABLEAU FINAL'!D25 -> 3 et plus | E26: ='[39]TABLEAU FINAL'!E25 -> -10.704813 | F26: ='[39]TABLEAU FINAL'!F25 -> 0.22606827 | G26: ='[39]TABLEAU FINAL'!G25 -> -0.01869584 | H26: ='[39]TABLEAU FINAL'!H25 -> -0.027647376
B27: ='[39]TABLEAU FINAL'!B26 -> Selon le quintile de pension
B28: ='[39]TABLEAU FINAL'!B27 -> Femmes | C28: ='[39]TABLEAU FINAL'!C27 -> Q1 | D28: ='[39]TABLEAU FINAL'!D27 -> 1 | E28: ='[39]TABLEAU FINAL'!E27 -> -3.5067899 | F28: ='[39]TABLEAU FINAL'!F27 -> 0.0042911853 | G28: ='[39]TABLEAU FINAL'!G27 -> -0.024779276 | H28: ='[39]TABLEAU FINAL'!H27 -> -0.023997855
D29: ='[39]TABLEAU FINAL'!D28 -> 2 | E29: ='[39]TABLEAU FINAL'!E28 -> -7.4575504 | F29: ='[39]TABLEAU FINAL'!F28 -> 0.024793529 | G29: ='[39]TABLEAU FINAL'!G28 -> -0.062359814 | H29: ='[39]TABLEAU FINAL'!H28 -> -0.062826089
D30: ='[39]TABLEAU FINAL'!D29 -> 3 et plus | E30: ='[39]TABLEAU FINAL'!E29 -> -12.005257 | F30: ='[39]TABLEAU FINAL'!F29 -> 0.017350712 | G30: ='[39]TABLEAU FINAL'!G29 -> -0.09451306 | H30: ='[39]TABLEAU FINAL'!H29 -> -0.096018169
C31: ='[39]TABLEAU FINAL'!C30 -> Q2 | D31: ='[39]TABLEAU FINAL'!D30 -> 1 | E31: ='[39]TABLEAU FINAL'!E30 -> -2.844539 | F31: ='[39]TABLEAU FINAL'!F30 -> 0.11040846 | G31: ='[39]TABLEAU FINAL'!G30 -> -0.0089890839 | H31: ='[39]TABLEAU FINAL'!H30 -> -0.013246054
D32: ='[39]TABLEAU FINAL'!D31 -> 2 | E32: ='[39]TABLEAU FINAL'!E31 -> -5.7455123 | F32: ='[39]TABLEAU FINAL'!F31 -> 0.15333061 | G32: ='[39]TABLEAU FINAL'!G31 -> -0.013751728 | H32: ='[39]TABLEAU FINAL'!H31 -> -0.018659096
D33: ='[39]TABLEAU FINAL'!D32 -> 3 et plus | E33: ='[39]TABLEAU FINAL'!E32 -> -10.763705 | F33: ='[39]TABLEAU FINAL'!F32 -> 0.25664381 | G33: ='[39]TABLEAU FINAL'!G32 -> -0.025352308 | H33: ='[39]TABLEAU FINAL'!H32 -> -0.033098582
C34: ='[39]TABLEAU FINAL'!C33 -> Q3 | D34: ='[39]TABLEAU FINAL'!D33 -> 1 | E34: ='[39]TABLEAU FINAL'!E33 -> -2.3582015 | F34: ='[39]TABLEAU FINAL'!F33 -> 0.13005024 | G34: ='[39]TABLEAU FINAL'!G33 -> -0.0022088799 | H34: ='[39]TABLEAU FINAL'!H33 -> -0.0074549377
D35: ='[39]TABLEAU FINAL'!D34 -> 2 | E35: ='[39]TABLEAU FINAL'!E34 -> -5.2533855 | F35: ='[39]TABLEAU FINAL'!F34 -> 0.16475746 | G35: ='[39]TABLEAU FINAL'!G34 -> -0.004666107 | H35: ='[39]TABLEAU FINAL'!H34 -> -0.010364382
D36: ='[39]TABLEAU FINAL'!D35 -> 3 et plus | E36: ='[39]TABLEAU FINAL'!E35 -> -7.3946919 | F36: ='[39]TABLEAU FINAL'!F35 -> 0.12392961 | G36: ='[39]TABLEAU FINAL'!G35 -> -0.0017702005 | H36: ='[39]TABLEAU FINAL'!H35 -> -0.0071313237
C37: ='[39]TABLEAU FINAL'!C36 -> Q4 | D37: ='[39]TABLEAU FINAL'!D36 -> 1 | E37: ='[39]TABLEAU FINAL'!E36 -> -2.3520008 | F37: ='[39]TABLEAU FINAL'!F36 -> 0.21385586 | G37: ='[39]TABLEAU FINAL'!G36 -> -0.0020846151 | H37: ='[39]TABLEAU FINAL'!H36 -> -0.0085710114
D38: ='[39]TABLEAU FINAL'!D37 -> 2 | E38: ='[39]TABLEAU FINAL'!E37 -> -5.1157175 | F38: ='[39]TABLEAU FINAL'!F37 -> 0.16299493 | G38: ='[39]TABLEAU FINAL'!G37 -> -0.0048609165 | H38: ='[39]TABLEAU FINAL'!H37 -> -0.0079275906
D39: ='[39]TABLEAU FINAL'!D38 -> 3 et plus | E39: ='[39]TABLEAU FINAL'!E38 -> -8.566665 | F39: ='[39]TABLEAU FINAL'!F38 -> 0.14691337 | G39: ='[39]TABLEAU FINAL'!G38 -> 0.0011765136 | H39: ='[39]TABLEAU FINAL'!H38 -> -0.0036203829
C40: ='[39]TABLEAU FINAL'!C39 -> Q5 | D40: ='[39]TABLEAU FINAL'!D39 -> 1 | E40: ='[39]TABLEAU FINAL'!E39 -> -2.8227468 | F40: ='[39]TABLEAU FINAL'!F39 -> 0.14335377 | G40: ='[39]TABLEAU FINAL'!G39 -> -0.0041894022 | H40: ='[39]TABLEAU FINAL'!H39 -> -0.0089065824
D41: ='[39]TABLEAU FINAL'!D40 -> 2 | E41: ='[39]TABLEAU FINAL'!E40 -> -5.9047715 | F41: ='[39]TABLEAU FINAL'!F40 -> 0.23777176 | G41: ='[39]TABLEAU FINAL'!G40 -> -0.00384903 | H41: ='[39]TABLEAU FINAL'!H40 -> -0.011927199
...

Sheet Tab B.4
A1: Tableau B.4 - Harmonisation de la majoration de pension à 10 % quel que soit le régime et uniformisation au-delà du troisième enfant - génération 2000
A2: Retour au sommaire
D4: ='[40]TABLEAU FINAL'!D3 -> Nombre d'enfants | E4: ='[40]TABLEAU FINAL'!E3 -> Durée validée totale moyenne (écart en trimestres) | F4: ='[40]TABLEAU FINAL'!F3 -> Âge de départ (écart en année) | G4: ='[40]TABLEAU FINAL'!G3 -> Pension moyenne 68 ans | H4: ='[40]TABLEAU FINAL'!H3 -> Pension moyenne CV
B5: ='[40]TABLEAU FINAL'!B4 -> Femmes | C5: ='[40]TABLEAU FINAL'!C4 -> 0 | D5: ='[40]TABLEAU FINAL'!D4 -> Ensemble | E5: ='[40]TABLEAU FINAL'!E4 -> - | F5: ='[40]TABLEAU FINAL'!F4 -> - | G5: ='[40]TABLEAU FINAL'!G4 -> 6.0163762e-05 | H5: ='[40]TABLEAU FINAL'!H4 -> 2.0398868e-05
B6: ='[40]TABLEAU FINAL'!B5 -> Hommes | C6: ='[40]TABLEAU FINAL'!C5 -> 0 | D6: ='[40]TABLEAU FINAL'!D5 -> Ensemble | E6: ='[40]TABLEAU FINAL'!E5 -> - | F6: ='[40]TABLEAU FINAL'!F5 -> - | G6: ='[40]TABLEAU FINAL'!G5 -> 8.1767504e-05 | H6: ='[40]TABLEAU FINAL'!H5 -> 3.6116339e-06
B7: ='[40]TABLEAU FINAL'!B6 -> Selon le nombre d'enfants | C7: ='[40]TABLEAU FINAL'!C6 -> 0 | D7: ='[40]TABLEAU FINAL'!D6 -> 0 | E7: ='[40]TABLEAU FINAL'!E6 -> 0 | F7: ='[40]TABLEAU FINAL'!F6 -> 0 | G7: ='[40]TABLEAU FINAL'!G6 -> 0 | H7: ='[40]TABLEAU FINAL'!H6 -> 0
B8: ='[40]TABLEAU FINAL'!B7 -> Femmes | C8: ='[40]TABLEAU FINAL'!C7 -> 0 | D8: ='[40]TABLEAU FINAL'!D7 -> 3 et plus | E8: ='[40]TABLEAU FINAL'!E7 -> - | F8: ='[40]TABLEAU FINAL'!F7 -> - | G8: ='[40]TABLEAU FINAL'!G7 -> 0.00020477093 | H8: ='[40]TABLEAU FINAL'!H7 -> 6.876366e-05
B9: ='[40]TABLEAU FINAL'!B8 -> Hommes | C9: ='[40]TABLEAU FINAL'!C8 -> 0 | D9: ='[40]TABLEAU FINAL'!D8 -> 3 et plus | E9: ='[40]TABLEAU FINAL'!E8 -> - | F9: ='[40]TABLEAU FINAL'!F8 -> - | G9: ='[40]TABLEAU FINAL'!G8 -> 0.00030772688 | H9: ='[40]TABLEAU FINAL'!H8 -> 4.8630599e-05
B10: ='[40]TABLEAU FINAL'!B9 -> Selon le régime d'affiliation | C10: ='[40]TABLEAU FINAL'!C9 -> 0 | D10: ='[40]TABLEAU FINAL'!D9 -> 0 | E10: ='[40]TABLEAU FINAL'!E9 -> 0 | F10: ='[40]TABLEAU FINAL'!F9 -> 0 | G10: ='[40]TABLEAU FINAL'!G9 -> 0 | H10: ='[40]TABLEAU FINAL'!H9 -> 0
B11: ='[40]TABLEAU FINAL'!B10 -> Femmes | C11: ='[40]TABLEAU FINAL'!C10 -> Mono Lura | D11: ='[40]TABLEAU FINAL'!D10 -> 3 et plus | E11: ='[40]TABLEAU FINAL'!E10 -> - | F11: ='[40]TABLEAU FINAL'!F10 -> - | G11: ='[40]TABLEAU FINAL'!G10 -> 0.00022800221 | H11: ='[40]TABLEAU FINAL'!H10 -> 0.00019980404
B12: ='[40]TABLEAU FINAL'!B11 -> 0 | C12: ='[40]TABLEAU FINAL'!C11 -> Mono FP-RS | D12: ='[40]TABLEAU FINAL'!D11 -> 3 et plus | E12: ='[40]TABLEAU FINAL'!E11 -> - | F12: ='[40]TABLEAU FINAL'!F11 -> - | G12: ='[40]TABLEAU FINAL'!G11 -> 0.0025733067 | H12: ='[40]TABLEAU FINAL'!H11 -> 0.0024439902
B13: ='[40]TABLEAU FINAL'!B12 -> 0 | C13: ='[40]TABLEAU FINAL'!C12 -> Mono MSAE-PLIB | D13: ='[40]TABLEAU FINAL'!D12 -> 3 et plus | E13: ='[40]TABLEAU FINAL'!E12 -> n.a | F13: ='[40]TABLEAU FINAL'!F12 -> n.a | G13: ='[40]TABLEAU FINAL'!G12 -> n.a | H13: ='[40]TABLEAU FINAL'!H12 -> n.a
B14: ='[40]TABLEAU FINAL'!B13 -> 0 | C14: ='[40]TABLEAU FINAL'!C13 -> Poly Lura-FP-RS | D14: ='[40]TABLEAU FINAL'!D13 -> 3 et plus | E14: ='[40]TABLEAU FINAL'!E13 -> - | F14: ='[40]TABLEAU FINAL'!F13 -> - | G14: ='[40]TABLEAU FINAL'!G13 -> -0.0051616366 | H14: ='[40]TABLEAU FINAL'!H13 -> -0.0052975024
B15: ='[40]TABLEAU FINAL'!B14 -> 0 | C15: ='[40]TABLEAU FINAL'!C14 -> Poly Lura-MSAE-PLIB | D15: ='[40]TABLEAU FINAL'!D14 -> 3 et plus | E15: ='[40]TABLEAU FINAL'!E14 -> - | F15: ='[40]TABLEAU FINAL'!F14 -> - | G15: ='[40]TABLEAU FINAL'!G14 -> 0.013472979 | H15: ='[40]TABLEAU FINAL'!H14 -> 0.012933182
B16: ='[40]TABLEAU FINAL'!B15 -> Hommes | C16: ='[40]TABLEAU FINAL'!C15 -> Mono Lura | D16: ='[40]TABLEAU FINAL'!D15 -> 3 et plus | E16: ='[40]TABLEAU FINAL'!E15 -> - | F16: ='[40]TABLEAU FINAL'!F15 -> - | G16: ='[40]TABLEAU FINAL'!G15 -> 0.001124153 | H16: ='[40]TABLEAU FINAL'!H15 -> 0.0010943477
... B31: ='[40]TABLEAU FINAL'!B30 -> 0 | C31: ='[40]TABLEAU FINAL'!C30 -> Q5 | D31: ='[40]TABLEAU FINAL'!D30 -> 3 et plus | E31: ='[40]TABLEAU FINAL'!E30 -> - | F31: ='[40]TABLEAU FINAL'!F30 -> - | G31: ='[40]TABLEAU FINAL'!G30 -> -0.00025631645 | H31: ='[40]TABLEAU FINAL'!H30 -> -0.0004905136
B33: Source : Drees – modèle Trajectoire

Sheet Tab B.5
A1: Tableau B.5 - Écart de masses de prestations de droit direct par régimes après mesures (en %)
A2: Retour au sommaire
D4: =[37]Ecarts_masses!D59 -> 2026 | E4: =[37]Ecarts_masses!E59 -> 2027 | F4: =[37]Ecarts_masses!F59 -> 2028 | G4: =[37]Ecarts_masses!G59 -> 2029 | H4: =[37]Ecarts_masses!H59 -> 2030 | I4: =[37]Ecarts_masses!I59 -> 2031 | J4: =[37]Ecarts_masses!J59 -> 2032 | K4: =[37]Ecarts_masses!K59 -> 2033 | ... AV4: =[37]Ecarts_masses!AV59 -> 2070
B5: Harmonisation 8 trimestres de MDA | C5: Tous régimes | D5: =[37]Ecarts_masses!D60 -> 0 | E5: =[37]Ecarts_masses!E60 -> 0 | F5: =[37]Ecarts_masses!F60 -> 0 | G5: =[37]Ecarts_masses!G60 -> 0 | H5: =[37]Ecarts_masses!H60 -> 0 | I5: =[37]Ecarts_masses!I60 -> 0 | J5: =[37]Ecarts_masses!J60 -> 0 | K5: =[37]Ecarts_masses!K60 -> 0 | ... AV5: =[37]Ecarts_masses!AV60 -> 0.0063119517
